{
    DataVersion: 3337,
    size: [7, 11, 7],
    data: [
        {pos: [2, 3, 2], state: "ae2lt:tianshu_amplifier_unit{formed:false}"},
        {pos: [3, 3, 2], state: "ae2lt:tianshu_amplifier_unit{formed:false}"},
        {pos: [4, 3, 2], state: "ae2lt:tianshu_amplifier_unit{formed:false}"},
        {pos: [2, 3, 3], state: "ae2lt:tianshu_amplifier_unit{formed:false}"},
        {pos: [3, 3, 3], state: "ae2lt:tianshu_amplifier_unit{formed:false}"},
        {pos: [4, 3, 3], state: "ae2lt:tianshu_amplifier_unit{formed:false}"},
        {pos: [2, 3, 4], state: "ae2lt:tianshu_amplifier_unit{formed:false}"},
        {pos: [3, 3, 4], state: "ae2lt:tianshu_amplifier_unit{formed:false}"},
        {pos: [4, 3, 4], state: "ae2lt:tianshu_amplifier_unit{formed:false}"},
        {pos: [2, 4, 1], state: "ae2lt:tianshu_amplifier_unit{formed:false}"},
        {pos: [3, 4, 1], state: "ae2lt:matter_warping_matrix_thread_unit_t1{formed:false}"},
        {pos: [4, 4, 1], state: "ae2lt:matter_warping_matrix_thread_unit_t1{formed:false}"},
        {pos: [1, 4, 2], state: "ae2lt:matter_warping_matrix_thread_unit_t1{formed:false}"},
        {pos: [2, 4, 2], state: "ae2lt:matter_warping_matrix_thread_unit_t1{formed:false}"},
        {pos: [3, 4, 2], state: "ae2lt:matter_warping_matrix_thread_unit_t1{formed:false}"},
        {pos: [4, 4, 2], state: "ae2lt:matter_warping_matrix_thread_unit_t1{formed:false}"},
        {pos: [5, 4, 2], state: "ae2lt:matter_warping_matrix_thread_unit_t1{formed:false}"},
        {pos: [1, 4, 3], state: "ae2lt:matter_warping_matrix_thread_unit_t1{formed:false}"},
        {pos: [2, 4, 3], state: "ae2lt:matter_warping_matrix_thread_unit_t1{formed:false}"},
        {pos: [3, 4, 3], state: "ae2lt:matter_warping_matrix_thermal_control_unit_t1{formed:false}"},
        {pos: [4, 4, 3], state: "ae2lt:matter_warping_matrix_thread_unit_t1{formed:false}"},
        {pos: [5, 4, 3], state: "ae2lt:matter_warping_matrix_thread_unit_t1{formed:false}"},
        {pos: [1, 4, 4], state: "ae2lt:matter_warping_matrix_thread_unit_t1{formed:false}"},
        {pos: [2, 4, 4], state: "ae2lt:matter_warping_matrix_thread_unit_t1{formed:false}"},
        {pos: [3, 4, 4], state: "ae2lt:matter_warping_matrix_thread_unit_t1{formed:false}"},
        {pos: [4, 4, 4], state: "ae2lt:matter_warping_matrix_thread_unit_t1{formed:false}"},
        {pos: [5, 4, 4], state: "ae2lt:matter_warping_matrix_thread_unit_t1{formed:false}"},
        {pos: [2, 4, 5], state: "ae2lt:matter_warping_matrix_thread_unit_t1{formed:false}"},
        {pos: [3, 4, 5], state: "ae2lt:matter_warping_matrix_thread_unit_t1{formed:false}"},
        {pos: [4, 4, 5], state: "ae2lt:matter_warping_matrix_thread_unit_t1{formed:false}"},
        {pos: [2, 5, 1], state: "ae2lt:matter_warping_matrix_thread_unit_t1{formed:false}"},
        {pos: [3, 5, 1], state: "ae2lt:matter_warping_matrix_thread_unit_t1{formed:false}"},
        {pos: [4, 5, 1], state: "ae2lt:matter_warping_matrix_thread_unit_t1{formed:false}"},
        {pos: [1, 5, 2], state: "ae2lt:matter_warping_matrix_thread_unit_t1{formed:false}"},
        {pos: [2, 5, 2], state: "ae2lt:matter_warping_matrix_thread_unit_t1{formed:false}"},
        {pos: [3, 5, 2], state: "ae2lt:matter_warping_matrix_thermal_control_unit_t1{formed:false}"},
        {pos: [4, 5, 2], state: "ae2lt:matter_warping_matrix_thread_unit_t1{formed:false}"},
        {pos: [5, 5, 2], state: "ae2lt:matter_warping_matrix_thread_unit_t1{formed:false}"},
        {pos: [1, 5, 3], state: "ae2lt:matter_warping_matrix_thread_unit_t1{formed:false}"},
        {pos: [2, 5, 3], state: "ae2lt:matter_warping_matrix_thermal_control_unit_t1{formed:false}"},
        {pos: [3, 5, 3], state: "ae2lt:matter_warping_matrix_stable_main_core{formed:false}"},
        {pos: [4, 5, 3], state: "ae2lt:matter_warping_matrix_thermal_control_unit_t1{formed:false}"},
        {pos: [5, 5, 3], state: "ae2lt:matter_warping_matrix_thread_unit_t1{formed:false}"},
        {pos: [1, 5, 4], state: "ae2lt:matter_warping_matrix_thread_unit_t1{formed:false}"},
        {pos: [2, 5, 4], state: "ae2lt:matter_warping_matrix_thread_unit_t1{formed:false}"},
        {pos: [3, 5, 4], state: "ae2lt:matter_warping_matrix_thermal_control_unit_t1{formed:false}"},
        {pos: [4, 5, 4], state: "ae2lt:matter_warping_matrix_thread_unit_t1{formed:false}"},
        {pos: [5, 5, 4], state: "ae2lt:matter_warping_matrix_thread_unit_t1{formed:false}"},
        {pos: [2, 5, 5], state: "ae2lt:matter_warping_matrix_thread_unit_t1{formed:false}"},
        {pos: [3, 5, 5], state: "ae2lt:matter_warping_matrix_thread_unit_t1{formed:false}"},
        {pos: [4, 5, 5], state: "ae2lt:matter_warping_matrix_thread_unit_t1{formed:false}"},
        {pos: [2, 6, 1], state: "ae2lt:matter_warping_matrix_thread_unit_t1{formed:false}"},
        {pos: [3, 6, 1], state: "ae2lt:matter_warping_matrix_thread_unit_t1{formed:false}"},
        {pos: [4, 6, 1], state: "ae2lt:matter_warping_matrix_thread_unit_t1{formed:false}"},
        {pos: [1, 6, 2], state: "ae2lt:matter_warping_matrix_thread_unit_t1{formed:false}"},
        {pos: [2, 6, 2], state: "ae2lt:matter_warping_matrix_thread_unit_t1{formed:false}"},
        {pos: [3, 6, 2], state: "ae2lt:matter_warping_matrix_thread_unit_t1{formed:false}"},
        {pos: [4, 6, 2], state: "ae2lt:matter_warping_matrix_thread_unit_t1{formed:false}"},
        {pos: [5, 6, 2], state: "ae2lt:matter_warping_matrix_thread_unit_t1{formed:false}"},
        {pos: [1, 6, 3], state: "ae2lt:matter_warping_matrix_thread_unit_t1{formed:false}"},
        {pos: [2, 6, 3], state: "ae2lt:matter_warping_matrix_thread_unit_t1{formed:false}"},
        {pos: [3, 6, 3], state: "ae2lt:matter_warping_matrix_thermal_control_unit_t1{formed:false}"},
        {pos: [4, 6, 3], state: "ae2lt:matter_warping_matrix_thread_unit_t1{formed:false}"},
        {pos: [5, 6, 3], state: "ae2lt:matter_warping_matrix_thread_unit_t1{formed:false}"},
        {pos: [1, 6, 4], state: "ae2lt:matter_warping_matrix_thread_unit_t1{formed:false}"},
        {pos: [2, 6, 4], state: "ae2lt:matter_warping_matrix_thread_unit_t1{formed:false}"},
        {pos: [3, 6, 4], state: "ae2lt:matter_warping_matrix_thread_unit_t1{formed:false}"},
        {pos: [4, 6, 4], state: "ae2lt:matter_warping_matrix_thread_unit_t1{formed:false}"},
        {pos: [5, 6, 4], state: "ae2lt:matter_warping_matrix_thread_unit_t1{formed:false}"},
        {pos: [2, 6, 5], state: "ae2lt:matter_warping_matrix_thread_unit_t1{formed:false}"},
        {pos: [3, 6, 5], state: "ae2lt:matter_warping_matrix_thread_unit_t1{formed:false}"},
        {pos: [4, 6, 5], state: "ae2lt:matter_warping_matrix_thread_unit_t1{formed:false}"},
        {pos: [2, 7, 2], state: "ae2lt:matter_warping_matrix_thread_unit_t1{formed:false}"},
        {pos: [3, 7, 2], state: "ae2lt:matter_warping_matrix_thread_unit_t1{formed:false}"},
        {pos: [4, 7, 2], state: "ae2lt:matter_warping_matrix_thread_unit_t1{formed:false}"},
        {pos: [2, 7, 3], state: "ae2lt:matter_warping_matrix_thread_unit_t1{formed:false}"},
        {pos: [3, 7, 3], state: "ae2lt:matter_warping_matrix_thread_unit_t1{formed:false}"},
        {pos: [4, 7, 3], state: "ae2lt:matter_warping_matrix_thread_unit_t1{formed:false}"},
        {pos: [2, 7, 4], state: "ae2lt:matter_warping_matrix_thread_unit_t1{formed:false}"},
        {pos: [3, 7, 4], state: "ae2lt:matter_warping_matrix_thread_unit_t1{formed:false}"},
        {pos: [4, 7, 4], state: "ae2lt:matter_warping_matrix_thread_unit_t1{formed:false}"}
    ],
    entities: [],
    palette: [
        "ae2lt:matter_warping_matrix_stable_main_core{formed:false}",
        "ae2lt:matter_warping_matrix_thermal_control_unit_t1{formed:false}",
        "ae2lt:tianshu_amplifier_unit{formed:false}",
        "ae2lt:matter_warping_matrix_thread_unit_t1{formed:false}"
    ]
}
